Workbook
Name ABANGARES: PROVINCIAS!$G$73:$G$76
Name ACOSTA: PROVINCIAS!$L$13:$L$17
Name AGUIRRE: PROVINCIAS!$F$86:$F$88
Name ALAJUELA: PROVINCIAS!$B$3:$P$3
Name ALAJUELA_: PROVINCIAS!$A$28:$A$41
Name ALAJUELITA: PROVINCIAS!$J$13:$J$17
Name ALFARO_RUIZ: PROVINCIAS!$K$28:$K$34
Name ALVARADO: PROVINCIAS!$F$46:$F$48
Name ASERRI: PROVINCIAS!$F$12:$F$18
Name ATENAS: PROVINCIAS!$E$28:$E$34
Name BARVA: PROVINCIAS!$B$61:$B$66
Name BELÉN: PROVINCIAS!$G$61:$G$63
Name BUENOS_AIRES: PROVINCIAS!$C$86:$C$93
Name CAÑAS: PROVINCIAS!$F$73:$F$77
Name CARRILLO: PROVINCIAS!$E$73:$E$76
Name CARTAGO: PROVINCIAS!$B$4:$I$4
Name CARTAGO_: PROVINCIAS!$A$46:$A$56
Name CORREDORES: PROVINCIAS!$J$86:$J$89
Name COTO_BRUS: PROVINCIAS!$H$86:$H$90
Name CURRIDABAT: PROVINCIAS!$R$13:$R$16
Name DESAMPARADOS: PROVINCIAS!$C$12:$C$23
Name DOTA: PROVINCIAS!$Q$13:$Q$15
Name EL_GUARCO: PROVINCIAS!$H$46:$H$49
Name ESCAZÚ: PROVINCIAS!$B$12:$B$14
Name ESPARZA: PROVINCIAS!$B$86:$B$90
Name FLORES: PROVINCIAS!$H$61:$H$63
Name GARABITO: PROVINCIAS!$K$86:$K$87
Name GOICOCHEA: PROVINCIAS!$H$13:$H$19
Name GOLFITO: PROVINCIAS!$G$86:$G$89
Name GRECIA: PROVINCIAS!$C$28:$C$35
Name GUÁCIMO: PROVINCIAS!$F$103:$F$107
Name GUANACASTE: PROVINCIAS!$B$6:$L$6
Name GUATUSO: PROVINCIAS!$O$28:$O$30
Name HEREDIA: PROVINCIAS!$B$5:$K$5
Name HEREDIA_: PROVINCIAS!$A$61:$A$65
Name HOJANCHA: PROVINCIAS!$K$73:$K$76
Name JIMÉNEZ: PROVINCIAS!$D$46:$D$48
Name LA_CRUZ: PROVINCIAS!$J$73:$J$76
Name LA_UNIÓN: PROVINCIAS!$C$46:$C$53
Name LEÓN_CORTES: PROVINCIAS!$T$13:$T$18
Name LIBERIA: PROVINCIAS!$A$73:$A$77
Name LIMÓN: PROVINCIAS!$B$8:$G$8
Name LIMÓN_: PROVINCIAS!$A$103:$A$106
Name LOS_CHILES: PROVINCIAS!$N$28:$N$31
Name MATINA: PROVINCIAS!$E$103:$E$105
Name MONTES_DE_OCA: PROVINCIAS!$O$13:$O$16
Name MONTES_DE_ORO: PROVINCIAS!$D$86:$D$88
Name MORA: PROVINCIAS!$G$13:$G$17
Name MORAVIA: PROVINCIAS!$N$13:$N$15
Name NANDAYURE: PROVINCIAS!$I$73:$I$78
Name NARANJO: PROVINCIAS!$F$28:$F$34
Name NICOYA: PROVINCIAS!$B$73:$B$79
Name OREAMUNO: PROVINCIAS!$G$46:$G$50
Name OROTINA: PROVINCIAS!$I$28:$I$32
Name OSA: PROVINCIAS!$E$86:$E$90
Name PALMARES: PROVINCIAS!$G$28:$G$34
Name PARAÍSO: PROVINCIAS!$B$46:$B$49
Name PARRITA: PROVINCIAS!$I$86
Name PEREZ_ZELEDÓN: PROVINCIAS!$S$13:$S$23
Name POÁS: PROVINCIAS!$H$28:$H$32

Sheet FORMULARIO
A1: MUNICIPALIDAD DE TILARÁN
A2: Proceso de Servicios Ciudadanos y Técnicos
R3: 2026
A4: DECLARACIÓN JURADA DEL IMPUESTO DE PATENTES PARA EL AÑO
A5: =VLOOKUP(R3,PARÁMETROS!D613:E617,2) -> Del 01 de enero 2025al 31 de diciembre de 2025
A9: NOMBRE DEL PATENTADO: | P9: Nº CÉDULA:
A10: REPRESENTANTE LEGAL: | P10: Nº CÉDULA:
A11: LUGAR O MEDIO PARA NOTIFICACIONES: | H11: Correo electrónico | P11: N° CELULAR:
A12: CORREO ELECTRÓNICO:
A13: NOMBRE DEL NEGOCIO: | P13: N° FINCA:
A14: TIPO RIESGO SANITARIO PSF: | I14: HORA APERTURA: | O14: HORA CIERRE:
A15: BAJO LA GRAVEDAD DE JURAMENTO Y CONFORME A LAS CONDICIONES QUE ESTABLECE EL CÓDIGO DE NORMAS Y PROCEDIMIENTOS TRIBUTARIOS Y LA LEY LICENCIAS PARA LAS ACTIVIDADES LUCRATIVAS DEL CANTÓN DE TILARÁN, N° 9505-2018, DECLARO QUE ESTE INFORME Y LOS DOCUMENTOS ADJUNTOS HAN SIDO EXAMINADOS POR MI; CONTIENEN UNA VERDADERA Y COMPLETA DECLARACIÓN, PARA EL CÁLCULO DEL IMPUESTO DE PATENTES.
E19: TILARÁN, | H19: DE | L19: DEL AÑO
A23: FIRMA DEL REPERESENTANTE LEGAL
A24: O PATENTADO
A26: ACTIVO NETO: | P26: ¢
A27: VENTAS O INGRESOS BRUTOS DEL PERÍODO: | P27: ¢
A28: COMPRAS DEL PERÍODO: | P28: ¢
A29: PERSONAL EMPLEADO: | S29: Colaboradores
A33: CANTIDAD ANUAL DE COMBUSTIBLE VENDIDO EN litros
A34: INGRESO ANUAL POR OTRAS ACTIVIDADES | P34: ¢
C35: Continúa al dorso…
A39: 4. REQUISITOS
C41: 1. En el caso de los contribuyentes del Régimen Tradicional, se deberá adjuntar copia del formulario D 101,
C42: IMPUESTO SOBRE UTILIDADES, correspondiente al período fiscal anterior.
C43: 2. En el caso de los contribuyentes inscritos en el Régimen de Tributación Simplificado, deberán presentar copia
C44: del formulario D 105 o DECLARACIÓN JURADA DEL RÉGIMEN DE TRIBUTACIÓN SIMPLIFICADA, correspondiente
C45: a los cuatro trimestres del período fiscal anterior.
C46: 3. Permiso Sanitario de Funcionamiento, o Certificado Veterinario de Operación, VIGENTE. (Verificación por parte
C47: Administración).
A48: 5. RECIBIDO
A50: EL PRESENTE FORMULARIO DEBERÁ SER LLENADO A MÁQUINA O CON LETRA IMPRENTA Y ABSOLUTAMENTE LEGIBLE.
A51: ADEMÁS, DEBERÁ PRESENTARSE EN LA PLATAFORMA DE SERVICIOS ANTES DEL | N51: =VLOOKUP(R3,PARÁMETROS!D613:F617,3,0) -> 46142
A52: PARA CONSULTAS A LOS TELÉFONOS 26 95 24 07, 26 95 24 09, 26 95 24 10 o 26 95 24 12

Sheet CONSTANCIA REQUISITOS
B2: MUNICIPALIDAD DE TILARÁN
B3: Proceso Servicios Ciudadanos y Técnicos
B4: Unidad Plataforma de Servicios
B6: CONSTANCIA DE VERIFICACIÓN DE REQUISITOS
B8: El(la) abajo firmante, funcionaro(a) municipal, hace constar que ante ésta administración se trámita FMT
B9: 021 Declaración de patente para 2021 bajo las siguientes condiciones:
B11: Nombre del patentado: | I11: =+FORMULARIO!F9 -> 0
B12: Cédula de identidad: | H12: =+FORMULARIO!R9 -> 0
B14: Verificado el expediente de la solicitud, se constata la presentación de los siguientes requisitos:
Z16: CUMPLE
B17: Formulario Declaración Jurada del Impuesto de patentes FMT 021 debidamente lleno | Z17: √
B18: Permiso Sanitario de Funcionamiento, emitido por el Ministerio de Salud, o el SENASA, VIGENTE. | Z18: x
B19: Copia Declaración Jurada del Impuesto sobre la Renta D 101 | Z19: √
B20: Copias (4) Declaraciones Juradas del Régimen de Tributación Simplificada D105 | Z20: NA
B21: Se apercibe al solicitante que deberá en el término de DIEZ días cumplir con el(los) requisito(s) pediente(s), caso contrario se ordenará el archivo de la solicitud sin mayor trámite. Tómese en cuenta que según el inciso i) del artículo 7º del Reglamento general de patentes comerciales y similares de la Municipalidad de Tilarán, la municipalidad podrá SUSPENDER la patente, cuando el patentado omita presentar la Declaración jurada de sus ventas brutas e ingresos brutos y de su renta líquida gravable, a que hace referencia el artículo 13 de éste Reglamento. Finalmente, considérese lo establecido en el artículo 22º de la Ley 9505-2018: Los patentados o sujetos pasivos que no presenten dentro del término establecido la declaración jurada del impuesto, con sus anexos, se harán acreedores de una multa equivalente a un cincuenta por ciento (50%) del monto anual del impuesto pagado el año anterior, la cual deberá pagarse conjuntamente con el impuesto del trimestre siguiente a las fechas establecidas en el artículo 20 de esta ley. En ningún caso esta multa será inferior a medio salario base, al día de hoy ¢ 231.100.00. El concepto de "salario base" usado en esta Ley es el establecido en el artículo 2 de la Ley No. 7337, de 5 de mayo de 1993.
B39: Annia Ramírez Rodríguez
B40: =VLOOKUP(B39,PARÁMETROS!E107:H129,4,0) -> PLATAFORMISTA

Sheet TOMA DATOS
C3: MUNICIPALIDAD DE TILARÁN
C4: Proceso de Servicios Ciudadanos y Técnicos
C5: FORMULARIO PARA LA RECALIFICACIÓN DEL IMPUESTO DE PATENTES
C7: A. DATOS DEL PATENTADO
C8: 1) Identificación patentado: | T8: 501930016
K9: =VLOOKUP(T8,ACTIVAS!$A$3:$AK$916,2,FALSE) -> JORGE ARTURO CHAVARRIA MONGE
C10: 2) Actividades autorizadas: | T10: =VLOOKUP(T8,ACTIVAS!A3:AK916,37,FALSE) -> 1
C11: 3) Actividad comercial: | T11: Otros | AE11: 501930016
C12: 4) Horario apertura: | T12: 0.29166667
C13: 5) Horario cierre: | T13: 0.70833333
C14: 6) Cantidad de Trabajadores: | T14: 2
C15: 7) Activo Neto | T15: 4325000
C16: 8) Ingresos brutos del período | T16: 12382000
C17: 9) Compras | T17: 0
C18: D. PARA USO DE LA OFICINA
C19: 10) Verificación de requisitos:
Y20: CUMPLE
C21: Formulario Declaración Jurada del Impuesto de patentes FMT 021 debidamente lleno | Y21: √
C22: Permiso Sanitario de Funcionamiento, emitido por el Ministerio de Salud, o el SENASA, VIGENTE. | Y22: √
C23: Copia Declaración Jurada del Impuesto sobre la Renta D 101 | Y23: NA
C24: Copias (4) Declaraciones Juradas del Régimen de Tributación Simplificada D105 | Y24: √
C50: MUNICIPALIDAD DE TILARAN
C51: Proceso de Servicios Ciudadanos y Técnicos
C52: Recalificación anual de patentes
C54: INFORMACIÓN GENERAL
C56: PATENTADO: | G56: =+'TOMA DATOS'!K9 -> JORGE ARTURO CHAVARRIA MONGE
C58: ACTIVIDADES AUTORIZADAS | Z58: =+'TOMA DATOS'!T10 -> 1
C60: DETALLE DEL CÁLCULO DEL IMPUESTO
C62: A. CÁLCULO DEL IMPUESTO ( Artículo 12, LEY 9505-2018 )
C64: De ¢ 0,00 hasta ¢ 750,000,000,00 | O64: 1.75
C65: De ¢750,000,001,00 hasta ¢ 1,500,000,000,00 | O65: 2.5
C66: De ¢ 1,500,000,001,00 hasta ¢ 3,000,000,000,00 | O66: 3.25
C67: De ¢ 3,000,000,001,00 hasta ¢ más | O67: 4.25
C68: IMPUESTO ANUAL | H68: =+IF(T16<750000000,T16*O64/1000,IF(T16<1500000000,T16*O65/1000,IF(T16<3000000000,T16*O66/1000,T16*O67/1000))) -> 21668.5 | P68: IMPUESTO TRIMESTRAL | V68: =+H68/4 -> 5417.125
C70: B. CALCULO IMPUESTO ( Artículo 125°, inciso b) Código de Normas y Procedimientos Tributarios )
C72: CANTIDAD | F72: PUESTO | N72: SALARIO | Q72: SALARIO GRUPAL | T72: CARGAS SOCIALES 31.36% | W72: COSTO MENSUAL
C73: 1 | F73: Licenciados Universitarios | N73: =VLOOKUP(F73,PARÁMETROS!M335:N344,2,0) -> 796921 | Q73: =+N73*C73 -> 796921 | T73: =+Q73*31.36% -> 249914.43 | W73: =+ROUND(T73+Q73,0) -> 1046835
C74: =+'TOMA DATOS'!T14-'TOMA DATOS'!C73 -> 1 | F74: Trabajadores en Ocupación No Calificada | N74: =IFERROR(VLOOKUP(F74,PARÁMETROS!M335:N344,2,0),"") -> 373092.3 | Q74: =IFERROR(N74*C74,"") -> 373092.3 | T74: =IFERROR(Q74*31.36%,"") -> 117001.75 | W74: =IFERROR(ROUND(T74+Q74,0),"") -> 490094
C75: COSTO ANUAL ESTIMADO POR REMUNERACIONES: | W75: =SUM(W73:AA74)*12 -> 18443148 | AB75: 0.4
C76: OTROS COSTOS ANUALES ESTIMADOS: | W76: =+W75*1.5 -> 27664722 | AB76: =+W76/W77 -> 0.6
...

Sheet ACTIVAS
A1: Identificación | B1: Nombre | C1: Nombre Representante Legal | D1: Identificación Representante Legal | E1: Tipo Identificación | F1: Celular | G1: Teléfono | H1: Correo | I1: Actividad Económica | J1: Nombre Comercial | K1: Identificación Propietario BienInmueble | L1: Nombre Propietario BienInmueble. | M1: Tipo Identificación Propietario BienInmueble | N1: Celular Propietario BienInmueble | O1: Teléfono Propietario BienInmueble | P1: Correo Electrónico Propietario BienInmueble | Q1: Actividad Económica Propietario BienInmueble | R1: Finca | S1: Duplicado | T1: Horizontal | U1: Derecho | V1: Provincia | W1: Cantón | X1: Distrito | Y1: Geo-referenciación-Latitud | Z1: Geo-referenciación-Longitud | AA1: Coordenada X | AB1: Coordenada Y | AC1: Dirección Física | AD1: Número Patente | AE1: Tipo Patente | AF1: Tipo Temporalidad | AG1: Monto Impuesto | AH1: Fecha Aprobación Patente | AI1: Fecha Cierre | AJ1: Estado
A2: 1 | B2: =1+A2 -> 2 | C2: =1+B2 -> 3 | D2: =1+C2 -> 4 | E2: =1+D2 -> 5 | F2: =1+E2 -> 6 | G2: =1+F2 -> 7 | H2: =1+G2 -> 8 | I2: =1+H2 -> 9 | ... AK2: =1+AJ2 -> 37
A3: 3101722970 | B3: 3-101-722970 SOCIEDAD ANONIMA | C3: ILEANA SANCHEZ VALVERDE | D3: 206350262 | E3: 1 | F3: 84199031 | G3: 84199031 | H3: arrientos@asesortotal.com | I3: COSMETICOS PERFUMERIA BISUTERIA | J3: FARMACIA DON GERARDO TILARAN | K3: 3101082143 | L3: INVERSIONES NIBELUNGOS SOCIEDAD ANONIMA | M3: N | N3: 88153066 | O3: 26955725 | P3: gwattsong@gmail.com | R3: 00113261 | S3: 0 | T3: 0 | U3: 000 | V3: 5 | W3: 08 | X3: 01 | AC3: FRENTE A GASOLINERA TILARAN | AD3: 0000000992 | AE3: C | AF3: P | AG3: 0 | AH3: 44012 | AJ3: A | AK3: =COUNTIF($A$3:A$917,A3) -> 2
A4: 208270217 | B4: FILANDER ANDRES SOTO CERDAS | F4: 86913093 | G4: 86913093 | H4: soto47916@gmail.com | J4: AMERICAN OUTLET | K4: 3101309683 | L4: AUTOTRANSPORTES JOCEKADI SOCIEDAD ANONIMA | M4: N | N4: 88106600 | P4: yenuro_86@hotmail.com | R4: 00006660 | S4: 0 | T4: 0 | U4: 000 | V4: 5 | W4: 08 | X4: 01 | AC4: FRENTE AL BANCO DE COSTA RICA | AD4: 0000001776 | AE4: C | AF4: P | AG4: 0 | AH4: 45153 | AJ4: A | AK4: =COUNTIF($A$3:A$917,A4) -> 1
A5: 155815120705 | B5: JUANA DEL C RODRIGUEZ VILCHEZ | F5: 61214294 | G5: 88233991 | H5: ciin.rodri@gmail.com | J5: H R BIZCOCHERIA ANTOJITOS DE MI TIERRA | K5: 502970875 | L5: HERNAN ALONSO ROJAS HERRERA | M5: N | N5: 88486482 | P5: alonsorojasharh@hotmail.com | R5: 00057576 | S5: 0 | T5: 0 | U5: 000 | V5: 5 | W5: 08 | X5: 01 | AC5: 50 M OESTE DE LA CRUZ ROJA TILARAN | AD5: 0000001796 | AE5: C | AF5: P | AG5: 0 | AH5: 45176 | AJ5: A | AK5: =COUNTIF($A$3:A$917,A5) -> 1
A6: 502640291 | B6: ORLANDO ALVARADO ARCE | F6: 85366309 | H6: orlandoal044@gmail.com | J6: MINISUPER LA AMISTAD | K6: 502640291 | L6: ORLANDO ALVARADO ARCE | M6: N | N6: 85366309 | P6: orlandoal044@gmail.com | R6: 00084466 | S6: 0 | T6: 0 | U6: 000 | V6: 5 | W6: 08 | X6: 04 | AC6: 200 M NORTE Y 50 OESTE DE LA IGLESIA CATOLICA LOS ANGELES | AD6: 0000001728 | AE6: C | AF6: P | AG6: 0 | AH6: 45086 | AJ6: A | AK6: =COUNTIF($A$3:A$917,A6) -> 1
A7: 155834652505 | B7: TANIA VANESSA ESPINOZA | F7: 61069366 | G7: 64709913 | H7: espinozatania568@gmail.com | J7: RESTAURANTE J & B | K7: 801360226 | L7: BELKIS ONEYDA MARADIAGA FLORES | M7: N | N7: 72630616 | O7: 72630616 | P7: belkisoneymaradiaga@gmail.com | R7: 00224764 | S7: 0 | T7: 0 | U7: 000 | V7: 5 | W7: 08 | X7: 01 | AC7: 1 K CAMINO A LIBANO DEL CEMENTERIO | AD7: 0000001753 | AE7: C | AF7: P | AG7: 0 | AH7: 45139 | AJ7: A | AK7: =COUNTIF($A$3:A$917,A7) -> 1
A8: 502710312 | B8: VIRGITA DEL CARMEN MENDEZ VEGA | F8: 62461759 | G8: 62222581 | H8: virgita17@gmail.com | J8: RESTAURANTE EL SABOR DE NUESTRO PUEBLO | K8: 502710312 | L8: VIRGITA DEL CARMEN MENDEZ VEGA | M8: N | N8: 62461759 | O8: 62222581 | P8: virgita17@gmail.com | R8: 00252904 | S8: 0 | T8: 0 | U8: 000 | V8: 5 | W8: 08 | X8: 02 | AC8: DE LA IGLESIA 300M.NORTE 100M.OESTE QDA.GRANDE | AD8: 0000001744 | AE8: C | AF8: P | AG8: 0 | AH8: 45119 | AJ8: A | AK8: =COUNTIF($A$3:A$917,A8) -> 2
A9: 502780472 | B9: ALEX ANTONIO ARTAVIA CONEJO | F9: 84126109 | G9: 84126109 | H9: artaviaalex01@gmail.com | I9: ABARROTES | J9: PULPERIA LA UNIÓN | K9: 502780472 | L9: ALEX ANTONIO ARTAVIA CONEJO | M9: N | N9: 84126109 | O9: 84126109 | P9: artaviaalex01@gmail.com | R9: 00104267 | S9: 0 | T9: 0 | U9: 000 | V9: 5 | W9: 08 | X9: 07 | AC9: 50 DEL CRUCE DE VENADO CAMINO A FORTUNA, LA UNIÓN | AD9: 0000001230 | AE9: C | AF9: P | AG9: 0 | AH9: 44391 | AJ9: A | AK9: =COUNTIF($A$3:A$917,A9) -> 1
A10: 601490937 | B10: ANA CECILIA DEL SOCORRO MONGE MENDOZA | F10: 85941813 | G10: 26951196 | H10: mainorlp@hotmail.com | I10: ABARROTES | J10: PULPERIA SAN RAFAEL | K10: 601490937 | L10: ANA CECILIA DEL SOCORRO MONGE MENDOZA | M10: N | N10: 85941813 | O10: 26951196 | P10: mainorlp@hotmail.com | R10: 00178832 | S10: 0 | T10: 0 | U10: 000 | V10: 5 | W10: 08 | X10: 04 | AC10: BARRIO SAN RAFAEL LOTE # 41 LOS ANGELES TILARAN | AD10: 0000000498 | AE10: C | AF10: P | AG10: 0 | AH10: 40562 | AJ10: A | AK10: =COUNTIF($A$3:A$917,A10) -> 1
A11: 602340703 | B11: ASVIN ELIZONDO ARIAS | F11: 87895888 | G11: 87895888 | H11: abastecedorlaplaza@gmail.com | I11: ABARROTES | J11: PULPERIA LA PLAZA | K11: 602340703 | L11: ASVIN ELIZONDO ARIAS | M11: N | N11: 87895888 | O11: 87895888 | P11: abastecedorlaplaza@gmail.com | R11: 00183291 | S11: 0 | T11: 0 | U11: 000 | V11: 5 | W11: 08 | X11: 04 | AC11: COSTADO SUR PLAZA DEPORTES QDA AZUL | AD11: 0000000511 | AE11: C | AF11: P | AG11: 0 | AH11: 39615 | AJ11: A | AK11: =COUNTIF($A$3:A$917,A11) -> 1
A12: 111110681 | B12: CARLOS ANDRES HERRERA RIVERA | F12: 85711157 | H12: carlosherrerar81@gmail.com | I12: ABARROTES | J12: PULPERIA LULU | K12: 501620778 | L12: FLOR MARIA DE DOLORES SOTO ELIZONDO | M12: N | N12: 84469153 | P12: florsotoelizondo@gmail.com | R12: 00060850 | S12: 0 | T12: 0 | U12: 000 | V12: 5 | W12: 08 | X12: 01 | AC12: 400 M ESTE DEL SALON COMUNAL BUENOS AIRES | AD12: 0000000056 | AE12: C | AF12: P | AG12: 0 | AH12: 43621 | AJ12: A | AK12: =COUNTIF($A$3:A$917,A12) -> 1
A13: 501710654 | B13: EFRAIN DE LAS PIEDADES ARIAS ZUÑIGA | F13: 88250549 | H13: darias_89@hotmail.com | I13: ABARROTES | J13: ABASTECEDOR DON EFRA | K13: 501050720 | L13: ANAIS MARIA DEL CARMEN LOPEZ ARTAVIA | M13: N | N13: 87904740 | O13: 26955642 | P13: darias_89@hotmail.com | R13: 00106528 | S13: 0 | T13: 0 | U13: 000 | V13: 5 | W13: 08 | X13: 01 | AC13: COSTADO NORTE DE LA CCSS, MINISUPER EFRAIN | AD13: 0000001994 | AE13: C | AF13: P | AG13: 0 | AH13: 45462 | AJ13: A | AK13: =COUNTIF($A$3:A$917,A13) -> 1
A14: 501460976 | B14: GERARDO MANUEL DELGADO CERDAS | F14: 83717783 | H14: gerardodelcer@gmail.com | I14: ABARROTES | J14: PULPERIA MAYNEL | K14: 501920883 | L14: ENA DAMARIS RUIZ ROJAS | M14: N | N14: 84851952 | O14: 84851952 | P14: damariruiz494@gmail.com | R14: 00056496 | S14: 0 | T14: 0 | U14: 000 | V14: 5 | W14: 08 | X14: 06 | AC14: CONTIGUO O IGLESIA CATOLICA DE SABALITO TIERRAS MORENAS | AD14: 0000000199 | AE14: C | AF14: P | AG14: 12611 | AH14: 36662 | AJ14: A | AK14: =COUNTIF($A$3:A$917,A14) -> 1
A15: 502530162 | B15: GERSAN GERARDO CHACON CORELLA | F15: 83375089 | G15: 83375089 | H15: chacon.gaby@hotmail.com | I15: ABARROTES | J15: " MINI SUPER GERSAN" | K15: 3101082143 | L15: INVERSIONES NIBELUNGOS SOCIEDAD ANONIMA | M15: N | N15: 88153066 | O15: 26955725 | P15: gwattsong@gmail.com | R15: 00039313 | S15: 0 | T15: 0 | U15: 000 | V15: 5 | W15: 08 | X15: 01 | AC15: DIAGONAL A LA GASOLINERA TILARÁN. | AD15: 0000000001 | AE15: C | AF15: P | AG15: 128609 | AH15: 36720 | AJ15: A | AK15: =COUNTIF($A$3:A$917,A15) -> 1
A16: 204820469 | B16: GIOVANNI RAMIREZ GAMBOA | F16: 62792322 | G16: 26938189 | H16: fale16cg@hotmail.com | I16: ABARROTES | J16: "MINISUPER CRISS" | K16: 3002066206 | L16: ASOCIACION DESARROLLO INTEGRAL DE CABECERAS DE CAÑ | M16: N | N16: 87134040 | P16: adicabeceras@gmail.com | R16: 00161381 | S16: 0 | T16: 0 | U16: 000 | V16: 5 | W16: 08 | X16: 02 | AC16: 50M N DEL ABAST CABECEREÑO DE CABECERAS (LOCALES COMERCIAL) | AD16: 0000000116 | AE16: C | AF16: P | AG16: 0 | AH16: 41716 | AJ16: A | AK16: =COUNTIF($A$3:A$917,A16) -> 1
A17: 3101590004 | B17: GMG COMERCIAL COSTA RICA SOCIEDAD ANONIMA | F17: 83386185 | H17: gmgcr91@grupomonge.com | I17: ABARROTES | J17: MONGE TILARAN | K17: 3101037575 | L17: ZONA LIBRE GUANACASTECA SOCIEDAD ANONIMA | M17: N | N17: 6690136 | R17: 00008073 | S17: 0 | T17: 0 | U17: 000 | V17: 5 | W17: 08 | X17: 01 | AC17: COSTADO SUR DEL PARQUE DE TILARAN | AD17: 0000001182 | AE17: C | AF17: P | AG17: 0 | AH17: 44307 | AJ17: A | AK17: =COUNTIF($A$3:A$917,A17) -> 3
A18: 204400422 | B18: JORGE ANTONIO HERRERA LOPEZ | F18: 87493502 | G18: 26955911 | H18: jorgeherreralopez68@gmail.com | I18: ABARROTES | J18: PULPERIA RIO CHIQUITO | K18: 500850246 | L18: MIREYA CLAUDINA DEL CARMEN LOPEZ ORTIZ | M18: N | N18: 83566527 | R18: 00900150 | S18: 0 | T18: 0 | U18: 000 | V18: 5 | W18: 08 | X18: 01 | AC18: 50M O ESCUELA RIO CHIQUITO TILARAN GTE | AD18: 0000001180 | AE18: C | AF18: P | AG18: 0 | AH18: 44300 | AJ18: A | AK18: =COUNTIF($A$3:A$917,A18) -> 1
A19: 503130961 | B19: KAROL DE LOS ANGELES MURILLO PICADO | F19: 83177021 | G19: 83177021 | H19: gjsiro@hotmail.com | I19: ABARROTES | J19: LA PULPERIA DE KAROL | K19: 3014042110 | L19: MUNICIPALIDAD DE TILARAN | M19: N | R19: 00053727 | S19: 0 | T19: 0 | U19: 000 | V19: 5 | W19: 08 | X19: 01 | AC19: MERCADO MUNICIPAL | AD19: 0000001987 | AE19: C | AF19: P | AG19: 0 | AH19: 45442 | AJ19: A | AK19: =COUNTIF($A$3:A$917,A19) -> 2
A20: 503840564 | B20: LUIS FERNANDO VILLALOBOS HERNANDEZ | F20: 87514783 | G20: 87514783 | H20: lvillaloboshernandez553@gmail.com | I20: ABARROTES | J20: PULPERÍA MARITA | K20: 502470608 | L20: FLOR IVETH DE LOS ANGELES HERNANDEZ FONSECA | M20: N | N20: 87212086 | P20: maritavh18@hotmail.com | R20: 00094445 | S20: 0 | T20: 0 | U20: 000 | V20: 5 | W20: 08 | X20: 01 | AC20: 25 M SUR QUEBRADA LA CABRA TILARA GTE | AD20: 0000002180 | AE20: C | AF20: P | AG20: 0 | AH20: 45848 | AJ20: A | AK20: =COUNTIF($A$3:A$917,A20) -> 1
A21: 504080854 | B21: MARIA FERNANDA PICADO BLANCO | F21: 71560174 | G21: 71560174 | H21: fer.picado9626@gmail.com | I21: ABARROTES | J21: PULPERIA JAAKOV | K21: 501930766 | L21: JORGE EDUARDO PICADO GONZALEZ | M21: N | N21: 60505906 | O21: 60505906 | P21: picadogonzalezjorge@gmail.com | R21: 00088227 | S21: 0 | T21: 0 | U21: 000 | V21: 5 | W21: 08 | X21: 01 | AC21: 700 ESTE 100 NORTE ESTADIO MUNICIPAL TILARAN | AD21: 0000002108 | AE21: C | AF21: P | AG21: 0 | AH21: 45702 | AJ21: A | AK21: =COUNTIF($A$3:A$917,A21) -> 1
A22: 400930671 | B22: MELITINA LUZ MARINA SEQUEIRA RODRIGUEZ | F22: 88288355 | G22: 88288355 | H22: vianeyelizondosequeira@gmail.com | I22: ABARROTES | J22: EL BUEN PRECIO | K22: 400930671 | L22: MELITINA LUZ MARINA SEQUEIRA RODRIGUEZ | M22: N | N22: 88288355 | O22: 88288355 | P22: vianeyelizondosequeira@gmail.com | R22: 00055512 | S22: 0 | T22: 0 | U22: 000 | V22: 5 | W22: 08 | X22: 07 | AC22: PULP BUEN PRECIO | AD22: 0000000149 | AE22: C | AF22: P | AG22: 0 | AH22: 36538 | AJ22: A | AK22: =COUNTIF($A$3:A$917,A22) -> 1
A23: 102830105 | B23: MISAEL FERNANDEZ ARGUEDAS | F23: 88263072 | G23: 88263072 | H23: misael.fernandez.a@outlook.com | I23: ABARROTES | J23: PULPERIA LA CONFIANZA | K23: 102830105 | L23: MISAEL FERNANDEZ ARGUEDAS | M23: N | N23: 88263072 | O23: 88263072 | P23: misael.fernandez.a@outlook.com | R23: 00115670 | S23: 0 | T23: 0 | U23: 000 | V23: 5 | W23: 08 | X23: 01 | AC23: 300 MTS SUR DEL BANCO DE COSTA RICA. | AD23: 0000000002 | AE23: C | AF23: P | AG23: 0 | AH23: 36544 | AJ23: A | AK23: =COUNTIF($A$3:A$917,A23) -> 1
A24: 502000255 | B24: OLGER ENRIQUE DEL CARMEN RODRIGUEZ MENDEZ | F24: 85203862 | H24: olger1124@gmail.com | I24: ABARROTES | J24: "ABASTECEDOR DIOS ES FIEL" | K24: 502000255 | L24: OLGER ENRIQUE DEL CARMEN RODRIGUEZ MENDEZ | M24: N | N24: 85203862 | P24: olger1124@gmail.com | R24: 00106824 | S24: 0 | T24: 0 | U24: 000 | V24: 5 | W24: 08 | X24: 03 | AC24: LAS PALMAS TRONADORA "ABASTECEDOR DIOS ES FIEL" | AD24: 0000000272 | AE24: C | AF24: P | AG24: 0 | AH24: 41548 | AJ24: A | AK24: =COUNTIF($A$3:A$917,A24) -> 1
A25: 504090023 | B25: PRISCILLA MARIA VILLEGAS JIMENEZ | F25: 86373489 | H25: prismaria1996@hotmail.com | I25: ABARROTES | J25: AZUKEP | K25: 502400197 | L25: ZULAY GERARDINA DE LOS ANGELES JIMENEZ SALAZAR | M25: N | N25: 86088966 | O25: 62616032 | R25: 00082211 | S25: 0 | T25: 0 | U25: 000 | V25: 5 | W25: 08 | X25: 02 | AC25: FRENTE A LA ESCUELA DE LAS NUBES | AD25: 0000001253 | AE25: C | AF25: P | AG25: 0 | AH25: 44454 | AJ25: A | AK25: =COUNTIF($A$3:A$917,A25) -> 1
A26: 204810525 | B26: ROSIBEL GERARDO CRUZ JIMENEZ | F26: 88247872 | G26: 26921174 | H26: yaricr84@hotmail.com | I26: ABARROTES | J26: PULPERIA CLAUDIO | K26: 502490456 | L26: JORGE ALFREDO RUIZ CORDOBA | M26: N | N26: 85292620 | P26: jorgeruizcor68@gmail.com | R26: 00125941 | S26: 0 | T26: 0 | U26: 000 | V26: 5 | W26: 08 | X26: 06 | AC26: 100M O 15M S IGLESIA CATOLICA TIERRA MORENAS TILARAN GTE | AD26: 0000000114 | AE26: C | AF26: P | AG26: 0 | AH26: 43178 | AJ26: A | AK26: =COUNTIF($A$3:A$917,A26) -> 1
A27: 3102898199 | B27: NUCLEO DE SERVICIOS CREATIVOS INTELIGENTES SOCIEDA | C27: JOSE CARLOS SEQUEIRA SEQUEIRA | D27: 503970813 | E27: 1 | F27: 83028219 | H27: jocarucr@gmail.com | I27: ACTIVIDADES DE CONSULTORIA EN GESTION | J27: GESTIONA: ESTRATEGIA Y PROYECTOS | N27: 89966996 | AD27: 0000002256 | AE27: C | AF27: P | AG27: 0 | AH27: 45974 | AJ27: A | AK27: =COUNTIF($A$3:A$917,A27) -> 3
A28: 112870620 | B28: ANDREA DE LOS ANGELES CHAN VIQUEZ | F28: 83262701 | G28: 83262701 | H28: campingazucar@gmail.com | I28: ACTIVIDADES TURISTICAS | J28: CAMPING Y MIRADOR MONTAÑA DE AZUCAR | K28: 800440515 | L28: IOK IO CHAN WONG | M28: N | N28: 88902455 | O28: 88902455 | P28: iokiochanwong@gmail.com | R28: 00016126 | S28: 0 | T28: 0 | U28: 000 | V28: 5 | W28: 08 | X28: 07 | AC28: 11800M E SECUELA UNION DE ARENAL | AD28: 0000000920 | AE28: C | AF28: P | AG28: 6948 | AH28: 43845 | AJ28: A | AK28: =COUNTIF($A$3:A$917,A28) -> 2
A29: 3002257283 | B29: ASOCIACION ADMINISTRADORA DE LA PRODUCCION AGRICOL | F29: 88555876 | G29: 88555876 | H29: cordobaavarcafrancisco@gmail.com | I29: ACTIVIDADES TURISTICAS | J29: PROYECTO ECOTURISTICO EL JILGUERO | K29: 2100042014 | L29: ESTADO MINISTERIO DE AMBIENTE Y ENERGIA | M29: N | R29: 00068046 | S29: 0 | T29: 0 | U29: 000 | V29: 5 | W29: 08 | X29: 06 | AC29: 750M N Y 2600M E DEL ANTIGUO RECIBIDOR DE CAFETIERRAS MOREN | AD29: 0000001110 | AE29: C | AF29: P | AG29: 0 | AH29: 44209 | AJ29: A | AK29: =COUNTIF($A$3:A$917,A29) -> 1
A30: 3101650234 | B30: AVENTURAS PARADICE PARK SOCIEDAD ANONIMA | C30: MAURICIO VARGAS RODRIGUEZ | D30: 602960548 | E30: 1 | F30: 88281809 | I30: ACTIVIDADES TURISTICAS | J30: AVENTURA PARADICE PARK S.A | N30: 83144435 | AD30: 0000000741 | AE30: C | AF30: P | AG30: 0 | AH30: 42969 | AJ30: A | AK30: =COUNTIF($A$3:A$917,A30) -> 1
A31: 501370730 | B31: CARLOS ENRIQUE DE JESUS SIRIAS ARIAS | F31: 87898617 | H31: ca9595395@gmail.com | I31: ACTIVIDADES TURISTICAS | J31: Finca La Colina | K31: 502980830 | L31: CARLOS ANTONIO ARIAS LOPEZ | M31: N | R31: 00122526 | S31: 0 | T31: 0 | U31: 000 | V31: 5 | W31: 08 | X31: 02 | AC31: De la Iglesia Católica, 1KM al sur, Quebrada Grande. | AD31: 0000001794 | AE31: C | AF31: P | AG31: 0 | AH31: 45176 | AJ31: A | AK31: =COUNTIF($A$3:A$917,A31) -> 1
A32: 3102645082 | B32: CHILCOUT TRAIL SOCIEDAD DE RESPONSABILIDAD LIMITAD | F32: 85714518 | G32: 26944667 | H32: bret@crparaiso.com | I32: ACTIVIDADES TURISTICAS | J32: CR PARAISO | K32: 3102645085 | L32: KELLY VALLEY PROPERTY SOCIEDAD DE RESPONSABILIDAD | M32: N | N32: 85714518 | O32: 26944750 | R32: 00050948 | S32: 0 | T32: 0 | U32: 000 | V32: 5 | W32: 08 | X32: 07 | AC32: 2KM.NORESTE DEL PUENTE DOS BOCAS N.ARENAL TILARAN | AD32: 0000000793 | AE32: C | AF32: P | AG32: 0 | AH32: 43672 | AJ32: A | AK32: =COUNTIF($A$3:A$917,A32) -> 1
A33: 3101864092 | B33: CUATRO Y UNO CINCO SOCIEDAD ANONIMA | F33: 88393764 | G33: 40007283 | H33: pablo@grupo415.com | I33: ACTIVIDADES TURISTICAS | J33: TREETOPIA PARK | K33: 3101864092 | L33: CUATRO Y UNO CINCO SOCIEDAD ANONIMA | M33: N | N33: 88393764 | O33: 40007283 | P33: pablo@grupo415.com | R33: 00010691 | S33: 0 | T33: 0 | U33: 000 | V33: 5 | W33: 08 | X33: 08 | AC33: 1.5 km noroeste del cruce entre Santa Elena y Las Nubes, San Gerardo. | AD33: 0000001663 | AE33: C | AF33: P | AG33: 0 | AH33: 44966 | AJ33: A | AK33: =COUNTIF($A$3:A$917,A33) -> 1
A34: 3008071089 | B34: JUNTA ADMINISTRATIVA COLEGIO TEC.AGROPECUARIO DE S | F34: 83030035 | G34: 26455390 | H34: 3008071089@junta.mep.go.cr | I34: ACTIVIDADES TURISTICAS | J34: RESERVA BOSQUE NUBOSO SANTA ELENA | K34: 2000045522 | L34: EL ESTADO | M34: E | N34: 85238964 | O34: 26958490 | R34: 00012833 | S34: 0 | T34: 0 | U34: 000 | V34: 5 | W34: 08 | X34: 03 | AC34: OFICINAS COLEGIO TECNICO AGROPECUARIO DE SANTA ELENA | AD34: 0000001089 | AE34: C | AF34: P | AG34: 43183 | AH34: 44167 | AJ34: A | AK34: =COUNTIF($A$3:A$917,A34) -> 3
A35: 504670767 | B35: MAYI ALEXANDRA NUÑEZ ARIAS | F35: 86928203 | H35: nunezmayi4@gmail.com | I35: ACTIVIDADES TURISTICAS | J35: CATARATAS & SENDEROS VIENTO FRESCO | K35: 3101861319 | L35: SENDEROS VIENTO FRESCO SOCIEDAD ANONIMA | M35: N | N35: 88683134 | O35: 22006836 | P35: jsalas1511@hotmail.com | R35: 00124425 | S35: 0 | T35: 0 | U35: 000 | V35: 5 | W35: 08 | X35: 02 | AC35: COSTADO N QDA LAS VUELTAS QDA GRANDE | AD35: 0000002055 | AE35: C | AF35: P | AG35: 0 | AH35: 45581 | AJ35: A | AK35: =COUNTIF($A$3:A$917,A35) -> 1
A36: 3101476392 | B36: PUENTES COLGANTES AVENTURA DE MONTEVERDE SOCIEDAD | F36: 83567601 | G36: 83567601 | H36: puentesaventura@hotmail.con | I36: ACTIVIDADES TURISTICAS | J36: PUENTES AVENTURA | K36: 203500079 | L36: CARLOS ALBERTO VARGAS RODRIGUEZ | M36: N | N36: 83567601 | O36: 26456413 | P36: puentesaventura@hotmail.com | R36: 00110846 | S36: 0 | T36: 0 | U36: 000 | V36: 5 | W36: 08 | X36: 02 | AC36: 1 KM NOROESTE DEL CANOPY AVENTURA, SAN BOSCO | AD36: 0000001158 | AE36: C | AF36: P | AG36: 0 | AH36: 44280 | AJ36: A | AK36: =COUNTIF($A$3:A$917,A36) -> 1
A37: 501850267 | B37: RAFAEL ANGEL DE GERARDO ARGUEDAS VILLALOBOS | F37: 85305414 | H37: arguedasrafaspc@gmail.com | I37: ACTIVIDADES TURISTICAS | J37: CATARATAS LA ROCA | K37: 3101226773 | L37: GANADERA MONGE ARIAS SOCIEDAD ANONIMA | M37: N | N37: 88664311 | O37: 88664311 | P37: monge.roger05@gmail.com | R37: 00140884 | S37: 0 | T37: 0 | U37: 000 | V37: 5 | W37: 08 | X37: 02 | AC37: 200 M NORTE Y 700 M OESTE DE LA IGLESIA CATOLICA, EL DOS, CABECERAS. | AD37: 0000001903 | AE37: C | AF37: P | AG37: 0 | AH37: 45334 | AJ37: A | AK37: =COUNTIF($A$3:A$917,A37) -> 3
A38: 501850267 | B38: RAFAEL ANGEL DE GERARDO ARGUEDAS VILLALOBOS | F38: 85305414 | H38: arguedasrafaspc@gmail.com | I38: ACTIVIDADES TURISTICAS | J38: DESLIZADOR ARCOIRIS | K38: 502010070 | L38: MARIA ISABEL ARGUEDAS VILLALOBOS | M38: N | N38: 84304418 | O38: 84304418 | P38: maria63isa@gmail.com | R38: 00247587 | S38: 0 | T38: 0 | U38: 000 | V38: 5 | W38: 08 | X38: 02 | AC38: 500 M NORTE DE LA IGLESIA DE LA FLORIDA, QUEBRADA GRANDE | AD38: 0000002047 | AE38: C | AF38: P | AG38: 0 | AH38: 45566 | AJ38: A | AK38: =COUNTIF($A$3:A$917,A38) -> 3
A39: 3102768312 | B39: RUTAS ANCESTRALES MONTEVERDE SOCIEDAD DE RESPONSAB | C39: HEIDY MARIA PEREZ BRAVO | D39: 503300655 | E39: 1 | F39: 84731414 | H39: hp115892@gmail.com | I39: ACTIVIDADES TURISTICAS | J39: RUTAS ANCESTRALES MONTEVERDE | K39: 501650284 | L39: MARTIN AURELIO RODRIGUEZ PEREZ | M39: N | N39: 86583937 | O39: 84108382 | P39: maurenr2311@gmail.com | R39: 00113908 | S39: 0 | T39: 0 | U39: 000 | V39: 5 | W39: 08 | X39: 08 | AC39: 50M.NORTE DE LA ESCUELA DE LAS NUBES | AD39: 0000000806 | AE39: C | AF39: P | AG39: 25859 | AH39: 43419 | AJ39: A | AK39: =COUNTIF($A$3:A$917,A39) -> 3
A40: 504250794 | B40: SABRINA GARCIA RODRIGUEZ | F40: 83201864 | H40: catarataelahora.cr@gmail.com | I40: ACTIVIDADES TURISTICAS | J40: Catarata El Ahora | K40: 501940197 | L40: EDWIN DE JESUS GARCIA CASTILLO | M40: N | N40: 89863179 | R40: 00007262 | S40: 0 | T40: 0 | U40: 000 | V40: 5 | W40: 08 | X40: 05 | AC40: DE LA IGLESIA CATOLICA LIBANO 1.5 KM AL SUR | AD40: 0000001899 | AE40: C | AF40: P | AG40: 0 | AH40: 45329 | AJ40: A | AK40: =COUNTIF($A$3:A$917,A40) -> 1
...

Sheet PARÁMETROS
U2: TIPO DE ZONA
B3: SI | C3: X | D3: CONDICIÓN | E3: MEDIOS DE NOTIFICACIÓN | I3: CUMPLE | J3: APLICA O NO | K3: USOS | P3: GESTIÓN | Q3: Permiso que señala la Ley General de Salud | U3: Habitación.
B4: NO | D4: Apoderado | E4: Fax | I4: SI | J4: Aplica | K4: USO CONFORME | N4: 1 | Q4: Certificado Veterinario de Operación requerido en la Ley General del Servicio Nacional de Salud Animal. | U4: Servicios de oficina.
D5: Representante Legal | E5: Correo electrónico | I5: NO | J5: No aplica | K5: USO NO CONFORME | N5: 0 | U5: Servicios para el comercio y abasto.
E6: Dirección representante o apoderado | I6: No aplica | U6: Servicios para la salud.
I7: MINISTERIO DE SALUD | Q7: Simplificación de Trámites | U7: Servicios para la educación.
B8: PROVINCIA-CANTON-DISTRITO | C8: PROVINCIA | D8: PROVINCIA-CANTÓN | F8: HORARIO | I8: Sección | J8: División | K8: Grupo | L8: Clase | M8: El Permiso Sanitario de Funcionamiento se otorga a los establecimientos que albergan las siguientes actividades | N8: Equivalencia al CIIU 3 | O8: Riesgo Sanitario Ministerio de Salud | Q8: Actividades de Comercialización y Servicios del SENASA | U8: Servicios religiosos.
F9: 00:00 am | U9: Servicios para la cultura y el deporte.
B10: SAN JOSE | C10: SAN JOSÉ | D10: San José | F10: 01:00 am | Q10: Columna2 | R10: Columna12 | U10: Servicios de alojamiento y turismo.
B11: SAN JOSE | C11: ALAJUELA | D11: SAN JOSE | F11: 02:00 am | Q11: Venta al por mayor de carne y productos cárnicos | R11: 40201 | U11: Instalaciones para la seguridad.
B12: El Carmen | C12: CARTAGO | D12: ESCAZU | F12: 03:00 am | Q12: Recibo, clasificación y primera venta de productos pesqueros. | R12: 40202 | U12: Servicios funerarios.
B13: Merced | C13: HEREDIA | D13: DESAMPARADOS | F13: 04:00 am | Q13: Venta al por mayor de productos lácteos | R13: 40203 | U13: Transporte y comunicación.
B14: Hospital | C14: GUANACASTE | D14: PURISCAL | F14: 05:00 am | Q14: Venta al por mayor de huevo fresco | R14: 40204 | U14: Industria.
B15: Catedral | C15: PUNTARENAS | D15: TARRAZU | F15: 06:00 am | Q15: Envasado y Venta al por mayor de miel y productos apícolas (polen, propóleo, jalea real) | R15: 40205 | U15: Instalaciones para la infraestructura.
B16: Zapote | C16: LIMÓN | D16: ASERRI | F16: 07:00 am | Q16: Venta al por mayor de productos pesqueros | R16: 40206
B17: San Fco.de Dos Ríos | D17: MORA | F17: 08:00 am | Q17: Envasado y venta al por mayor de jarabes | R17: 40207
B18: Uruca | D18: GOICOECHEA | F18: 09:00 am | Q18: Venta al por mayor de medicamentos veterinarios | R18: 40301
B19: Mata Redonda | D19: SANTA ANA | F19: 10:00 am | Q19: Venta al por mayor de productos afines | R19: 40303
B20: Pavas | D20: ALAJUELITA | F20: 11:00 am | Q20: Venta al por mayor de medicamentos veterinarios de medicina alternativa | R20: 40304
B21: Hatillo | D21: VASQUEZ DE CORONADO | F21: 12:00 m.d | Q21: Venta al por mayor de productos afines de medicina alternativa | R21: 40305
B22: San Sebastián | D22: ACOSTA | F22: 01:00 pm | Q22: Venta al por mayor de alimentos, mezclas y premezclas para animales | R22: 40401
B23: ESCAZU | D23: TIBAS | F23: 02:00 pm | Q23: Venta al por mayor de materias primas para alimentación animal | R23: 40402
B24: Escazú | D24: MORAVIA | F24: 03:00 pm | Q24: Reempaque de alimentos destinados a la alimentación animal | R24: 40403
B25: San Antonio | D25: MONTES DE OCA | F25: 04:00 pm | Q25: Venta al por menor de mascotas o animales domésticos | R25: 40501
B26: San Rafael | D26: TURRUBARES | F26: 05:00 pm | Q26: Venta al por menor de animales acuáticos ornamentales | R26: 40503
B27: DESAMPARADOS | D27: DOTA | F27: 06:00 pm | Q27: Venta al por menor de animales silvestres autorizados | R27: 40504
B28: Desamparados | D28: CURRIDABAT | F28: 07:00 pm | Q28: Expendio de carne y productos cárnicos | R28: 40601
B29: San Miguel | D29: PEREZ ZELEDON | F29: 08:00 pm | Q29: Expendio de productos pesqueros | R29: 40602 | U29: 4. Servicios para la salud.
B30: San Juan de Dios | D30: LEON CORTES | F30: 09:00 pm | Q30: Expendio de lácteos | R30: 40603
B31: San Rafael Arriba | F31: 10:00 pm | Q31: Expendio de huevos | R31: 40604 | U31: 4.1 Consultorios médicos.
B32: San Antonio | D32: Alajuela | F32: 11:00 pm | Q32: Expendio de miel y productos apícolas | R32: 40605 | U32: 4.2 Clínicas y centros de salud.
B33: Frailes | D33: ALAJUELA | F33: 11:59 pm | Q33: Reempaque de productos de origen animal con fines de venta minorista | R33: 40606 | U33: 4.3 Hospitales, sanatorios, maternidades, y centros de rehabilitación.
B34: Patarrá | D34: SAN RAMON | Q34: Expendio de carne de caballo | R34: 40607
B35: San Cristóbal | D35: GRECIA | F35: CONICIÓN DEL LOCAL | Q35: Venta al por menor de medicamentos veterinarios | R35: 40801 | U35: 5. Servicios para la educación.
B36: Rosario | D36: SAN MATEO | Q36: Venta al por menor de productos afines | R36: 40802
B37: Damas | D37: ATENAS | F37: Excelente | Q37: Venta al por menor de medicamentos de medicina alternativa | R37: 40803 | U37: 5.1 Educación preparatoria y educación primaria.
B38: San Rafael Abajo | D38: NARANJO | F38: Buena | Q38: Venta al por menor de productos afines de medicina alternativa | R38: 40804 | U38: 5.2 Educación media: académica, de artes y oficios y tecnológicas o vocacionales.
B39: Gravilias | D39: PALMARES | F39: Regular | Q39: Venta al por menor de productos destinados a la alimentación animal | R39: 40901 | U39: 5.3 Educación superior, institutos técnicos, centros de capacitación, academias profesionales, colegios universitarios y universidades.
B40: PURISCAL | D40: POAS | F40: Deficiente | Q40: Reempaque de productos destinados a la alimentación animal en punto de venta | R40: 40902 | U40: 5.4 Educación física y artística: escuelas de natación, música, baile, artes marciales, modelos, pintura, escultura, actuación y fotografía.
B41: Santiago | D41: OROTINA | Q41: Servicio de hospitalización veterinaria | R41: 60101
...

Sheet PROVINCIAS
A1: PROVINCIA | B1: CANTON
A2: SAN_JOSE | B2: SAN_JOSE | C2: ESCAZÚ | D2: DESAMPARADOS | E2: PURISCAL | F2: TARRAZU | G2: ASERRI | H2: MORA | I2: GOICOCHEA | J2: SANTA_ANA | K2: ALAJUELITA | L2: VASQUEZ_DE_CORONADO | M2: ACOSTA | N2: TIBAS | O2: MORAVIA | P2: MONTES_DE_OCA | Q2: TURRUBARES | R2: DOTA | S2: CURRIDABAT | T2: PEREZ_ZELEDÓN | U2: LEÓN_CORTES
A3: ALAJUELA | B3: ALAJUELA_ | C3: SAN_RAMON | D3: GRECIA | E3: SAN_MATEO | F3: ATENAS | G3: NARANJO | H3: PALMARES | I3: POÁS | J3: OROTINA | K3: SAN_CARLOS | L3: ALFARO_RUIZ | M3: VALVERDE_VEGA | N3: UPALA | O3: LOS_CHILES | P3: GUATUSO
A4: CARTAGO | B4: CARTAGO_ | C4: PARAÍSO | D4: LA_UNIÓN | E4: JIMÉNEZ | F4: TURRIALBA | G4: ALVARADO | H4: OREAMUNO | I4: EL_GUARCO
A5: HEREDIA | B5: HEREDIA_ | C5: BARVA | D5: SANTO_DOMINGO | E5: SANTA_BÁRBARA | F5: SAN_RAFAEL | G5: SAN_ISIDRO | H5: BELÉN | I5: FLORES | J5: SAN_PABLO | K5: SARAPIQUÍ
A6: GUANACASTE | B6: LIBERIA | C6: NICOYA | D6: SANTA_CRUZ | E6: BAGACES | F6: CARRILLO | G6: CAÑAS | H6: ABANGARES | I6: TILARAN | J6: NANDAYURE | K6: LA_CRUZ | L6: HOJANCHA
A7: PUNTARENAS | B7: PUNTARENAS_ | C7: ESPARZA | D7: BUENOS_AIRES | E7: MONTES_DE_ORO | F7: OSA | G7: AGUIRRE | H7: GOLFITO | I7: COTO_BRUS | J7: PARRITA | K7: CORREDORES | L7: GARABITO
A8: LIMÓN | B8: LIMÓN_ | C8: POCOCI | D8: SIQUIRRES | E8: TALAMANCA | F8: MATINA | G8: GUÁCIMO
A10: SAN JOSE
A12: SAN_JOSE | B12: Escazú | C12: Desamparados | D12: Santiago | E12: San Marcos | F12: Aserri | G12: MORA | H12: GOICOECHEA | I12: SANTA ANA | J12: ALAJUELITA | K12: VASQUEZ DE CORONADO | L12: ACOSTA | M12: TIBAS | N12: MORAVIA | O12: MONTES DE OCA | P12: TURRUBARES | Q12: DOTA | R12: CURRIDABAT | S12: PEREZ ZELEDON | T12: LEON CORTES
A13: El Carmen | B13: San Antonio | C13: San Miguel | D13: Mercedes Sur | E13: San Lorenzo | F13: Tarbaca | G13: Colón | H13: Guadalupe | I13: Santa Ana | J13: Alajuelita | K13: San Isidro | L13: San Ignacio | M13: San Juan | N13: San Vicente | O13: San Pedro | P13: San Pablo | Q13: Santa María | R13: Curridabat | S13: San Isidro de El General | T13: San Pablo
A14: Merced | B14: San Rafael | C14: San Juan de Dios | D14: Barbacoas | E14: San Carlos | F14: Vuelta de Jorco | G14: Guayabo | H14: San Francisco | I14: Salitral | J14: San Josecito | K14: San Rafael | L14: Guaitíl | M14: Cinco Esquinas | N14: San Jerónimo | O14: Sabanilla | P14: San Pedro | Q14: Jardín | R14: Granadilla | S14: General | T14: San Andrés
A15: Hospital | C15: San Rafael Arriba | D15: Grifo Alto | F15: San Gabriel | G15: Tabarcia | H15: Calle Blancos | I15: Pozos | J15: San Antonio | K15: Dulce Nombre de Jesús | L15: Palmichal | M15: Anselmo Llorente | N15: Trinidad | O15: Mercedes | P15: San Juan de Mata | Q15: Copey | R15: Sánchez | S15: Daniel Flores | T15: Llano Bonito
A16: Catedral | C16: San Antonio | D16: San Rafael | F16: Legua | G16: Piedras Negras | H16: Mata de Plátano | I16: Uruca | J16: Concepción | K16: Patalillo | L16: Cangrejal | M16: León XIII | O16: San Rafael | P16: San Luis | R16: Tirrases | S16: Rivas | T16: San Isidro
A17: Zapote | C17: Frailes | D17: Candelarita | F17: Monterrey | G17: Picagres | H17: Ipís | I17: Piedades | J17: San Felipe | K17: Cascajal | L17: Sabanillas | M17: Colima | S17: San Pedro | T17: Santa Cruz
A18: San Fco.de Dos Ríos | C18: Patarrá | D18: Desamparaditos | F18: Salitrillos | H18: Rancho Redondo | I18: Brasil | S18: Platanares | T18: San Antonio
A19: Uruca | C19: San Cristóbal | D19: San Antonio | H19: Purral | S19: Pejibaye
A20: Mata Redonda | C20: Rosario | D20: Chires | S20: Cajón
A21: Pavas | C21: Damas | S21: Barú
A22: Hatillo | C22: San Rafael Abajo | S22: Río Nuevo
A23: San Sebastián | C23: Gravilias | S23: Páramo
A25: ALAJUELA
A27: ALAJUELA | B27: SAN RAMON | C27: GRECIA | D27: SAN MATEO | E27: ATENAS | F27: NARANJO | G27: PALMARES | H27: POAS | I27: OROTINA | J27: SAN CARLOS | K27: ALFARO RUIZ | L27: VALVERDE VEGA | M27: UPALA | N27: LOS CHILES | O27: GUATUSO
A28: Alajuela | B28: San Ramón | C28: Grecia | D28: San Mateo | E28: Atenas | F28: Naranjo | G28: Palmares | H28: San Pedro | I28: Orotina | J28: Quesada | K28: Zarcero | L28: Sarchí Norte | M28: Upala | N28: Los Chiles | O28: San Rafael
A29: San José | B29: Santiago | C29: San Isidro | D29: Desmonte | E29: Jesús | F29: San Miguel | G29: Zaragoza | H29: San Juan | I29: Mastate | J29: Florencia | K29: Laguna | L29: Sarchí Sur | M29: Aguas Claras | N29: Caño Negro | O29: Buenavista
A30: Carrizal | B30: San Juan | C30: San José | D30: Jesús María | E30: Mercedes | F30: San José | G30: Buenos Aires | H30: San Rafael | I30: Hacienda Vieja | J30: Buenavista | K30: Tapezco | L30: Toro Amarillo | M30: San José o Pizote | N30: El Amparo | O30: Cote
A31: San Antonio | B31: Piedades Norte | C31: San Roque | E31: San Isidro | F31: Cirrí Sur | G31: Santiago | H31: Carrillos | I31: Coyolar | J31: Aguas Zarcas | K31: Guadalupe | L31: San Pedro | M31: Bijagua | N31: San Jorge
A32: Guácima | B32: Piedades Sur | C32: Tacares | E32: Concepción | F32: San Jerónimo | G32: Candelaria | H32: Sabana Redonda | I32: Ceiba | J32: Venecia | K32: Palmira | L32: Rodríguez | M32: Delicias
A33: San Isidro | B33: San Rafael | C33: Río Cuarto | E33: San José | F33: San Juan | G33: Esquipulas | J33: Pital | K33: Zapote | M33: Dos Ríos
A34: Sabanilla | B34: San Isidro | C34: Puente de Piedra | E34: Santa Eulalia | F34: Rosario | G34: Granja | J34: Fortuna | K34: Brisas | M34: Yolillal
A35: San Rafael | B35: Angeles | C35: Bolívar | J35: Tigra
A36: Río Segundo | B36: Alfaro | J36: Palmera
A37: Desamparados | B37: Volio | J37: Venado
A38: Turrúcares | B38: Concepción | J38: Cutris
A39: Tambor | B39: Zapotal | J39: Monterrey
A40: La Garita | B40: Peñas Blancas | J40: Pocosol
A41: Sarapiquí
A43: CARTAGO
A45: CARTAGO | B45: PARAISO | C45: LA UNION | D45: JIMENEZ | E45: TURRIALBA | F45: ALVARADO | G45: OREAMUNO | H45: EL GUARCO
A46: Oriental | B46: Paraíso | C46: Tres Ríos | D46: Juan Viñas | E46: Turrialba | F46: Pacayas | G46: San Rafael | H46: El Tejar
...

Sheet UNICOMER
E2: 2022
E3: TRIMESTRAL | G3: ANUAL
B4: INGRESO BRUTO CURACAO | E4: 7.9047004e+08 | F4: =E4/E7 -> 0.39789476
B5: INGRESO BRUTO GOLLO | E5: 1.1961609e+09 | F5: =E5/E7 -> 0.60210524
E7: =E5+E4 -> 1.9866309e+09
E9: TRIMESTRAL | G9: ANUAL
B10: Impuesto 2022 | E10: =#REF! -> #REF! | G10: =E10*4 -> #REF!
B12: IMPUESTO TRIMESTRAL CURACAO | E12: =E10*F4 -> #REF!
B13: IMPUESTO TRIMESTRAL GOLLO | E13: =E10*F5 -> #REF!
N14: 2021
E15: =SUM(E12:E14) -> #REF! | N15: TRIMESTRAL
K16: CURACAO LINEA BLANCA | N16: 1146065.1 | O16: =N16/N18 -> 0.93925817 | P16: 93.93
E17: TRIMESTRAL | G17: ANUAL | K17: CURACAO ABARROTES | N17: 74116.04 | O17: =N17/N18 -> 0.060741833 | P17: 6.07
B18: CURACAO LINEA BLANCA | E18: =E12*F18 -> #REF! | F18: 0.9393 | G18: =E18*4 -> #REF! | N18: =SUM(N16:N17) -> 1220181.2 | O18: =SUM(O16:O17) -> 1 | P18: =SUM(P16:P17) -> 100
B19: CURACAO ABARROTES | E19: =E12*F19 -> #REF! | F19: 0.0607 | G19: =E19*4 -> #REF!
E20: =SUM(E18:E19) -> #REF! | G20: =SUM(G18:G19) -> #REF! | K20: EL GOLLO LINEA BLANCA | N20: 438987.59 | O20: =N20/N22 -> 0.91651299 | P20: 91.65
K21: EL GOLLO ABARROTES | N21: 39988.26 | O21: =N21/N22 -> 0.083487007 | P21: 8.35
B22: EL GOLLO LINEA BLANCA | E22: =E13*F22 -> #REF! | F22: 0.9165 | G22: =E22*4 -> #REF! | N22: =SUM(N20:N21) -> 478975.85 | O22: =SUM(O20:O21) -> 1 | P22: =SUM(P20:P21) -> 100
B23: EL GOLLO ABARROTES | E23: =E13*F23 -> #REF! | F23: 0.0835 | G23: =E23*4 -> #REF!
E24: =SUM(E22:E23) -> #REF! | G24: =SUM(G22:G23) -> #REF!
G26: =G20+G24 -> #REF!

Sheet PAYUTE
D13: NENEN | E13: 50947668 | F13: =+E13/E16 -> 0.36473999
D14: PAYUTE | E14: 88734488 | F14: =+E14/E16 -> 0.63526001
E16: =SUM(E13:E15) -> 139682156
D17: 2022 | E17: =+#REF! -> #REF!
D20: NENEN | E20: =+E17*F13 -> #REF! | F20: =+E20*4 -> #REF!
D21: PAYUTE | E21: =+E17*F14 -> #REF! | F21: =+E21*4 -> #REF!
E23: =SUM(E20:E22) -> #REF!

Sheet GESSA
A1: gess
B2: INGRESO BRUTO ARENAL | E2: 9.6334089e+08 | G2: =E2/E5 -> 0.61552251
B3: INGRESO BRUTO TILARÁN | E3: 6.0173735e+08 | G3: =E3/E5 -> 0.38447749
E5: =E3+E2 -> 1.5650782e+09
B8: Impuesto Anual 2022 | E8: =1271626*4 -> 5086504
B10: INGRESO BRUTO ARENAL | E10: =E8*G2 -> 3130857.7
B11: INGRESO BRUTO TILARÁN | E11: =E8*G3 -> 1955646.3
E13: =SUM(E10:E12) -> 5086504

Sheet BNCR
B2: INGRESO BRUTO ARENAL | E2: 3.0976022e+08 | G2: =E2/E5 -> 0.34006234
B3: INGRESO BRUTO TILARÁN | E3: 6.0113225e+08 | G3: =E3/E5 -> 0.65993766
E5: =E3+E2 -> 9.1089247e+08
B8: Impuesto trimestral 2022 | E8: =#REF! -> #REF!
B10: INGRESO BRUTO ARENAL | E10: =E8*G2 -> #REF!
B11: INGRESO BRUTO TILARÁN | E11: =E8*G3 -> #REF!
E13: =SUM(E10:E12) -> #REF!

Sheet colono
B15: 000021 FERRETERIA | H15: 2010417.2 | I15: =+H15/$H$20 -> 0.39500076
A16: 2021 | B16: 000020 MATERIALES CONSTRUCCION. | H16: 2010417.2 | I16: =+H16/$H$20 -> 0.39500076
B17: 000021 FERRETERIA | H17: 952700.96 | I17: =+H17/$H$20 -> 0.18718384
B18: 000021 FERRETERIA | H18: 116118.63 | I18: =+H18/$H$20 -> 0.022814642
H20: =SUM(H15:H19) -> 5089654 | I20: =SUM(I15:I19) -> 1
G22: 4807161
B23: 000021 FERRETERIA | H23: =+G22*I15 -> 1898832.3 | I23: =+H23/G22 -> 0.39500076
A24: 2022 | B24: 000020 MATERIALES CONSTRUCCION. | H24: =+G22*I16 -> 1898832.3 | I24: =+H24/G22 -> 0.39500076
B25: 000021 FERRETERIA | H25: =+G22*I17 -> 899822.84 | I25: =+H25/G22 -> 0.18718384
B26: 000021 FERRETERIA | H26: =+G22*I18 -> 109673.66 | I26: =+H26/G22 -> 0.022814642
H28: =SUM(H23:H27) -> 4807161 | I28: =SUM(I23:I26) -> 1
G30: 4807161
B31: 000021 FERRETERIA | H31: =+H23*4 -> 7595329 | I31: =+H31/G30 -> 1.580003
A32: 2022 | B32: 000020 MATERIALES CONSTRUCCION. | H32: =+H24*4 -> 7595329 | I32: =+H32/G30 -> 1.580003
B33: 000021 FERRETERIA | H33: =+H25*4 -> 3599291.3 | I33: =+H33/G30 -> 0.74873534
B34: 000021 FERRETERIA | H34: =+H26*4 -> 438694.63 | I34: =+H34/G30 -> 0.091258569
H36: =SUM(H31:H35) -> 19228644 | I36: =SUM(I31:I34) -> 4
