Workbook
Name PROVINCIA: [1]PROVINCIAS!$A$2:$A$8

Sheet FACTORES
B5: MUNICIPALIDAD DE TILARAN
B6: Administración Tributaria Municipal
B7: COBROS
B9: FACTORES DE UTILIDAD
B10: Manual de cobros I.F.A.M.
B11: Calculo del Impuesto de patentes
B13: ACTIVIDAD COMERCIAL | C13: MARGEN DE UTILIDAD | D13: FACTOR
B15: Carnes | C15: 0.2 | D15: 6
B16: Abarrotes
B17: Productos farmacéuticos
B18: Productos para la agricultura
B19: Materiales de construcción
B21: Vestimenta | C21: 0.25 | D21: 5
B22: Calzado
B23: Ferretería
B24: Librería
B26: Electrodomésticos | C26: 0.33 | D26: 4
B27: Vehículos
B28: Artículos de boutique
B30: Almentos preparados | C30: 0.5 | D30: 3
B31: Sodas, cafeterías, fondas restaurantes . . .
B33: Otros | C33: 0.33 | D33: 4

Sheet FORMULARIO
B2: MUNICIPALIDAD DE TILARAN
B3: PROCESO DE SERVICIOS CIUDADANOS Y TÉCNICOS
B5: FORMULARIO DE SOLICITUD DE PATENTES PARA VENTAS AMBULANTES O ESTACIONARIOS EN VÍAS PÚBLICAS | AK5: :
B7: a. INFORMACIÓN GENERAL DEL SOLICITANTE
B8: NOMBRE SOLICITANTE: | U8: CÉDULA:
B9: DOMICILIO:
B10: TELÉFONO: | M10: CEL: | U10: CORREO:
B11: LUGAR O MEDIO PARA NOTIFICACIONES | R11: FIRMA solicitante
B13: b. INFORMACIÓN ADICIONAL
B15: TIPO DE PATENTE: | P15: LÍNEA COMERCIAL:
B16: ZONA DE VENTA: | N16: UBICACIÓN: (sólo estacionarios):
B17: EDAD DEL SOLICITANTE: | M17: INVENTARIO SEMANAL MERCADERÍA
B19: c. REQUISITOS
B21: X | D21: a) Presentar la cédula de identidad o cédula de residencia libre de condición o DIMEX en caso de ser extranjero
B22: X | D22: b) Póliza de riesgos del trabajo que emite el Instituto Nacional de Seguros al efecto. Si se trata de actividades lucrativas explotadas por el núcleo
D23: familiar podrá presentarse el correspondiente certificado de exoneración extendido por el INS. Art 202 del Código de Trabajo.
B24: X | D24: c) El solicitante se encuentra al día en el pago de los tributos municipales en favor de la Municipalidad de Tilarán.
B25: X | D25: d) Cien colones en timbres fiscales o pago del entero.
B26: X | D26: e) Ser mayor de edad o menor de edad debidamente autorizado, costarricense por nacimiento o naturalización o extranjero establecido permanente-
D27: mente en el país, con residencia no menor de 10 años, sometido al régimen jurídico y a la jurisdicción de los tribunales de la República, salvo lo que
D28: sobre el particular consignen los tratados o convenios internacionales.
B29: X | D29: f) Constancia de inscripción ante la Dirección General de Tributación Directa.
B30: X | D30: g) EL SOLICITANTE está al día en el pago de las obligaciones con la Caja Costarricense de Seguro Social.
B31: X | D31: h) Queda prohibido el establecimiento de puestos fijos o transitorios de elaboración o venta de alimentos en calles, parques o aceras, u otros lugares públicos, con excepción de las ventas en ferias debidamente autorizadas de conformidad con las disposiciones reglamentarias correspondientes.
B33: NA | D33: i) Para el caso de los puestos estacionarios, el solicitante deberá aportar acuerdo municipal de adjudicación del mismo
B35: d. ACUSE DE RECIBIDO
B36: REQUISITOS RECIBIDOS Y REVISADOS POR:
B37: FECHA: | D37: =NOW() -> 45349.499

Sheet EX INS-F-D0139
G2: INSTITUTO NACIONAL DE SEGUROS
G3: Seguro Obligatorio de Riesgos del Trabajo
G4: Solicitud de validación del artículo 194 del Código de Trabajo
B6: REQUISITOS | C6: I. Original del documento de identificación del interesado, vigente y en buen estado. II. Si el interesado (a) autoriza a otra persona para presentar esta solicitud a su nombre, debe aportar: • Carta de autorización. • Fotocopia del documento de identificación del interesado (a). • Original del documento de identificación de la persona autorizada, vigente y en buen estado. III. A efecto de verificar la actividad económica a exonerar, deberá presentar en original o fotocopia, alguno de los documentos que se citan: • Permiso sanitario de funcionamiento vigente. • Último recibo de la patente pagado o comprobante digital. • Permiso o concesión vigente para transporte de personas. • Si se encuentra tramitando por primera vez el permiso respectivo, podrá presentar el formulario de solicitud debidamente cumplimentado y sellado por la institución correspondiente o en su defecto, comprobante digital cuando el trámite se pueda realizar en línea. No obstante, en el caso del servicio de transporte de personas, solo debe presentar el formulario de “Solicitud de validación del artículo 194 del Código de Trabajo” debidamente cumplimentado. • Cualquier documento de respaldo de la actividad económica, expedido por la entidad reguladora en ese sector.
B27: DECLARACIÓN | C27: 1. Yo | D27: =+FORMULARIO!H8 -> 0 | K27: , N° identificación | N27: =+FORMULARIO!X8 -> 0
C28: declaro que la información suministrada en este documento es fiel reflejo de las condiciones en que realizaré la actividad, para la cual solicito la validación de conformidad con lo establecido en el artículo 194 del Título IV del Código de Trabajo, que a la letra señala: “Sin perjuicio de que, a solicitud del interesado, se pueda expedir el seguro contra riesgos del trabajo, estarán excluidos de las disposiciones de este Título: a) La actividad laboral familiar de personas físicas, entendida ésta como la que se ejecuta entre los cónyuges, o los que viven como tales, entre éstos y sus ascendientes y descendientes, en beneficio común, cuando en forma indudable no exista relación de trabajo. b) Los trabajadores que realicen actividades por cuenta propia, entendidos como los que trabajan solos o asociados, en forma independiente, y que no devengan salario.” Asimismo, que los datos consignados son veraces y se pueden comprobar en cualquier momento y que, con la firma de este documento doy fe que conozco y acepto la responsabilidad existente por cualquier información suministrada que se compruebe ser falsa, todo de acuerdo con el marco legal costarricense.
B50: INFORMACIÓN ACTIVIDAD ECONÓMICA | C50: 2. Nombre del negocio: | I50: =+FORMULARIO!#REF! -> #REF!
C51: 3. Dirección del negocio: | I51: =+FORMULARIO!G16 -> 0
C52: 4. Provincia: | E52: =+'[1] FMT 104 TOMA DATOS'!I34 -> GUANACASTE | J52: 5. Cantón: | L52: =+'[1] FMT 104 TOMA DATOS'!U34 -> TILARAN
C53: 6. Distrito: | E53: =+FORMULARIO!G16 -> 0
C54: 7. Correo electrónico: | H54: =+FORMULARIO!X10 -> 0
C55: 8. Teléfono del negocio: | G55: =+FORMULARIO!E10 -> 0 | J55: 9. Número celular: | M55: =+FORMULARIO!O10 -> 0
C56: 10. Actividad económica del negocio: | J56: =+FORMULARIO!#REF! -> #REF!
C57: 11. La actividad económica señalada anteriormente, la realiza:
D58: NO | E58: Con trabajadores a su cargo
D60: NO | E60: Asociado:
D61: Nombre | M61: N° identificación
B69: INFORMACIÓN ACTIVIDAD ECONÓMICA | D69: NO | E69: Con familiares:
D70: a. Seleccione la o las personas con quien ejecuta la actividad laboral.
D71: b. Selecciones si existe o no relación laboral; es decir, si hay o no remuneración, subordinación y prestación de un servicio.
D73: ¿Existe relación laboral? | I73: Nombre | M73: N° identificación
G74: SI | H74: NO
C75: Cónyuge / conviviente
C76: Papá / mamá | H76: X
C77: Suegro (a) | H77: X
C78: Hijo (a) | H78: X
C79: Hijastro (a) | H79: X
C80: Abuelo (a) | H80: X
C81: Bisabuelo (a) | H81: X
C82: Nieto (a) | H82: X
C83: Bisnieto (a) | H83: X
C84: Otros: | H84: X
D86: SI | E86: Sólo
C87: 12. Fecha de solicitud | I87: 13. Firma del interesado (a)
C88: =TODAY() -> 45349
C94: USO EXCLUSIVO DEL INSTITUTO NACIONAL DE SEGUROS
B95: VALIDACIÓN ART. 194 | C95: 14. De conformidad con lo dispuesto en el artículo 194 del Código de Trabajo y una vez analizada la información declarada anteriormente por la persona interesada, se tiene como resultado que:
D99: No está en la obligación de tomar la póliza del Seguro Obligatorio de Riesgos del Trabajo.
D101: Por tanto, esta condición rige a partir de la fecha de esta validación y se extenderá hasta un año calendario.
D103: Sin embargo, esta condición cesará automáticamente si los aspectos declarados en esta solicitud que consta en poder del Instituto Nacional de Seguros varían, o se inicia una relación laboral en los términos del Código de Trabajo, por lo que la persona interesada quedará obligada a adquirir la póliza del Seguro Obligatorio de Riesgos del Trabajo.
...

Sheet CALCULO AMBULANTES
B2: MUNICIPALIDAD DE TILARAN
B3: PROCESO DE SERVICIOS CIUDADANOS Y TÉCNICOS
B4: SOLICITUD DE PATENTE COMERCIAL PARA VENTAS AMBULANTES O ESTACIONARIAS EN VÍAS PÚBLICAS
B5: Calculo del Impuesto
B6: INFORMACIÓN GENERAL
B7: NOMBRE DEL SOLICITANTE: | G7: =+FORMULARIO!H8 -> 0 | R7: CÉDULA: | U7: =+FORMULARIO!X8 -> 0
B8: DIRECCIÓN: | D8: =+FORMULARIO!H11 -> 0
B9: PATENTE COMERCIAL SOLICITADA: | G9: =+FORMULARIO!G15 -> 0 | O9: CÓDIGO: | Q9: =VLOOKUP(G9,PARAMETROS!B47:C48,2,FALSE) -> #N/A
B11: PERSONAL POR EMPLEAR INICIALMENTE
B12: CANTIDAD | C12: PUESTO | K12: SALARIO | N12: SALARIO GRUPAL | Q12: CARGAS SOCIALES 31.36% | T12: COSTO MENSUAL
B13: 1 | C13: Trabajador Especializado Genéricos | K13: =VLOOKUP(C13,PARAMETROS!B6:D14,2,0) -> 421970.02 | N13: =+K13*B13 -> 421970.02 | Q13: =+N13*31.36% -> 132329.8 | T13: =+ROUND(Q13+N13,0) -> 554300
B14: COSTO ANUAL ESTIMADO a): | T14: =SUM(T13:X13)*12 -> 6651600
B15: FACTORES DE EVALUACIÓN ADICIONALES
B16: FACTOR | H16: RESULTADO | Q16: PUNTAJE
B17: INVENTARIO MERCADERÍA SEMANAL | H17: =+FORMULARIO!W17 -> 0 | Q17: =VLOOKUP(H17,PARAMETROS!G5:I7,2,0) -> #N/A
B18: ZONA DE VENTA | H18: =+FORMULARIO!G16 -> 0 | Q18: =VLOOKUP(H18,PARAMETROS!G9:I11,2,0) -> #N/A
B19: EDAD DEL SOLICITANTE | H19: =+FORMULARIO!I17 -> 0 | Q19: =VLOOKUP(H19,PARAMETROS!G14:I82,2,0) -> #N/A
B20: e) PUNTAJE TOTAL: | E20: =SUM(Q17:S19) -> #N/A
B21: f) TOTAL GASTOS ESTIMADOS:
B22: a * ( 1 +e/90 ) | D22: =+T14*(1+(E20/90)) -> #N/A
B23: g) FACTOR DE UTILIDAD: | F23: 3 | H23: =(100%/(F23-1)) -> 0.5
B24: h) INGRESO BRUTO ESPERADO: | G24: =+(D22/(F23-1))*F23 -> #N/A | K24: =+G24/12 -> #N/A | O24: * mes
B25: ( f / g-1) * g
B26: i) RENTA LÍQUIDA ESPERADA: | G26: =+G24-D22 -> #N/A | K26: =+G26/D22 -> #N/A
B27: j) IMPUESTO ANUAL 1.75/1000: | F27: =+ROUND(+G24*(1.75/1000),0) -> #N/A
B28: l) IMPUESTO TRIMESTRAL: | F28: =+ROUND(SUM(F27:F27)/4,0) -> #N/A
B29: ll) A PARTIR DEL TRIMESTRE: | G29: 2023-01
B31: CODIGO: | F31: ACTIVIDAD:
B32: =+Q9 -> #N/A | F32: =+G9 -> 0 | S32: =+F28/H36 -> #N/A
B34: 1191020000000-02 | F34: Timbre 2% impuesto de patentes, ley 7788 | S34: =+ROUND(F28*2%,0) -> #N/A
B36: TOTAL ACTIVIDADES AUTORIZADAS | H36: 1
B37: EJECUTADO POR ( firma ): | E37: =+FORMULARIO!M36 -> 0
B38: FECHA: | C38: =+FORMULARIO!D37 -> 45349.499
B39: REVISADO POR ( firma ): | E39: Zeidy Campos Artavia
B40: FECHA: | C40: =NOW() -> 45349.499
B41: APROBADO POR ( firma ): | E41: José Antonio Rodríguez Herrera
B42: FECHA: | C42: =+C40 -> 45349.499
D44: =+FORMULARIO!H8 -> 0 | O44: =+G9 -> 0

Sheet RESOLUCION AMBULANTES
C2: Municipalidad de Tilarán
C3: PROCESO DE SERVICIOS CIUDADANOS Y TÉCNICOS
Q5: =+'CALCULO AMBULANTES'!C40 -> 45349.499
C6: Vista la solicitud de licencia comercial presentada mediante el formulario FMT 011 por:
C7: =+'CALCULO AMBULANTES'!G7 -> 0 | Q7: cédula nº: | T7: =+'CALCULO AMBULANTES'!U7 -> 0
C8: ésta Coordinación resuelve de conformidad con el artículo setenta y nueve, siguientes y concor-
C9: dantes del Código Municipal APROBAR el desarrollo de la siguiente actividad:
C11: =+'CALCULO AMBULANTES'!B32 -> #N/A | I11: =+'CALCULO AMBULANTES'!#REF! -> #REF!
C13: La actividad comercial autorizada, se desarrollará en | Q13: =+FORMULARIO!G16 -> 0
C14: debiendo el autorizado ajustarse a la legislación que a continuación se indica: | W14: √
C16: √ | D16: ARTÍCULO Nº 90 bis DEL CÓDIGO MUNICIPAL: La licencia referida en el artículo 88, podrá suspenderse por falta de pago de dos o más trimestres, o bien por incumplimiento de los requisitos ordenados en las leyes para el desarrollo de la actividad. ...
C18: √ | D18: ARTÍCULO 20 LEY N° 9505. Todos los patentados tienen la obligación de presentar, cada año, la declaración jurada del impuesto ante la Municipalidad de Tilarán y anexar la fotocopia de la declaración del impuesto sobre la renta del período sujeto a gravar, debidamente recibida por la Dirección General de Tributación, cualquiera que sea la cuantía de sus ingresos o ventas brutas obtenidas. En el mes de enero de cada año, podrá solicitarse en Plataforma de Servicios, el respectivo formulario.
C21: √ | D21: ARTICULO 5° DEL REGLAMENTO DE VENTAS AMBULANTES Y ESTACIONARIAS EN VÍAS PÚBLICAS: Las licencias municipales se podrán suspender por: a) Por falta de pago de dos o más trimestres. b) En caso de que el concesionario o el núcleo familiar no la utilice en forma regular, por espacio mínimo de tres meses. c) Cuando se compruebe que se ha transferido el derecho a otra persona o que el concesionario o núcleo familiar no atienda el puesto. d) Por denuncia formal comprobada ante la Municipalidad contra el concesionario, por motivos inmorales y contra las buenas costumbres. e) Cambio de línea comercial establecida en la adjudicación de la licencia, sin autorización previa de la Municipalidad. f) No acatamiento a las órdenes emitidas por la Municipalidad para el buen funcionamiento. g) Cuando de alguna forma se violente el orden público y la tranquilidad pública. h) Cuando el patentado omita presentar la Declaración jurada de sus ventas brutas e ingresos brutos, a que hace referencia el artículo 20 de la Ley n° 9505 Licencias para actividades lucrativas del cantón de Tilarán.
C28: √ | D28: ARTICULO 10° DEL REGLAMENTO DE VENTAS AMBULANTES Y ESTACIONARIAS EN VÍAS PÚBLICAS: No podrán ubicarse puestos obstruyendo ventanas, entradas, esquinas donde converjan las zonas de seguridad peatonal, frente a monumentos nacionales; en la parada de autobuses y el Mercado Municipal.
C31: √ | D31: ARTICULO 11° DEL REGLAMENTO DE VENTAS AMBULANTES Y ESTACIONARIAS EN VÍAS PÚBLICAS: Quedan terminantemente prohibidas en ventanas de comercios establecidos cuando los dependientes y/o productos tengan que ocupar la vía pública para ejercer la actividad.
C34: √ | D34: ARTICULO 20° DEL REGLAMENTO DE VENTAS AMBULANTES Y ESTACIONARIAS EN VÍAS PÚBLICAS: La solicitud de cambio de línea comercial deberá ser tramitada ante la Coordinación del Proceso de Servicios Ciudadanos y Técnicos, mediante escrito.
M38: =+'CALCULO AMBULANTES'!E39 -> Zeidy Campos Artavia
M39: =VLOOKUP(M38,PARAMETROS!B17:D28,3,0) -> ASISTENTE TÉCNICO
M42: =+'CALCULO AMBULANTES'!E41 -> José Antonio Rodríguez Herrera
M43: =VLOOKUP(M42,PARAMETROS!B17:E34,3,0) -> COORDINADOR
C44: Original | E44: =+C7 -> 0
C45: Copia 1: | E45: Oficina de gestión de cobros

Sheet CERTIFICADO
C3: MUNICIPALIDAD DE TILARÁN
C4: Proceso de Servicos Ciudadanos y Técnicos
C7: CERTIFICADO DE PATENTE COMERCIAL
C9: LÍNEA COMERCIAL AUTORIZADA: | L9: =+'CALCULO AMBULANTES'!G9 -> 0
C10: ZONA DE VENTA: | H10: =+'RESOLUCION AMBULANTES'!Q13 -> 0
C11: ACTIVIDADES COMERCIALES AUTORIZADAS POR LA MUNICIPALIDAD DE TILARÁN:
C13: 1 | D13: =+'CALCULO AMBULANTES'!#REF! -> #REF!
C14: =1+C13 -> 2 | D14: NINGUNA OTRA
C15: =1+C14 -> 3 | D15: NINGUNA OTRA
C17: NOMBRE DEL PATENTADO: | J17: =+'CALCULO AMBULANTES'!G7 -> 0 | AA17: N° CEDULA: | AD17: =+'CALCULO AMBULANTES'!U7 -> 0
C19: EL PORTADOR DE LA CÉDULA NÚMERO: | M19: =+AD17 -> 0 | R19: HA CUMPLIDO CON LOS REQUISITOS NECESARIOS PARA OTORGARLE LA
C20: LICENCIA MUNICIPAL HASTA EL 30 DE ABRIL DEL AÑO: | T20: 2023 | V20: ////Colóquese en lugar visible////
C29: =+'RESOLUCION AMBULANTES'!M38 -> Zeidy Campos Artavia
C30: =+'RESOLUCION AMBULANTES'!M39 -> ASISTENTE TÉCNICO
C31: OBSERVACIONES:

Sheet PARAMETROS
B2: SALARIOS
B4: Decreto Nº 43633-MTSS, publicado en el Alcance No.159 de La Gaceta No. 143, del 28072022. Rige 1º de julio del 2022
B5: CATEGORÍAS | C5: SIGLAS | D5: SALARIOS | E5: Columna1 | G5: MÁS DE ¢ 500.000.00 | H5: 30 | I5: puntos
B6: Trabajador no Calificado Genéricos | C6: 330299.11 | D6: TNCG: | G6: DE ¢ 250.0001.00 ¢ 500.000.00 | H6: 20 | I6: puntos
B7: Trabajador Semicalificado Genéricos | C7: 356329.6 | D7: TSCG | G7: DE ¢ 0.00 A ¢ 250.000 | H7: 10 | I7: puntos
B8: Trabajador Calificado Genéricos | C8: 371610.27 | D8: TCG:
B9: Técnico Medio Educación Diver. | C9: 389421.08 | D9: TMED | G9: Todo el cantón | H9: 30 | I9: puntos
B10: Trabajador Especializado Genéricos | C10: 421970.02 | D10: TEG: | G10: Distrito Central | H10: 20 | I10: puntos
B11: Técnico de Educación Superior | C11: 479918.65 | D11: TEdS | G11: Otros distritos | H11: 10 | I11: puntos
B12: Diplomados de Educación Superior | C12: 518330.07 | D12: DES:
B13: Bachiller Universitario | C13: 587908.98 | D13: Bach: | G13: EDAD DEL SOLICITANTE
B14: Licenciado Universitario | C14: 705514.95 | D14: Lic.: | G14: 18 | H14: 30 | I14: puntos
G15: =1+G14 -> 19 | H15: 30 | I15: puntos
G16: =1+G15 -> 20 | H16: 30 | I16: puntos
A17: 1 | B17: Frayman Perez Ramirez | C17: 503170889 | D17: ASISTENTE TÉCNICO | E17: fperez@tilaran.go.cr | G17: =1+G16 -> 21 | H17: 30 | I17: puntos
A18: =1+A17 -> 2 | B18: Yamileth Carvajal Manzanares | C18: 502140609 | D18: ASISTENTE TÉCNICO | E18: ycarvajal@tilaran.go.cr | G18: =1+G17 -> 22 | H18: 30 | I18: puntos
A19: =1+A18 -> 3 | B19: Zeidy Campos Artavia | C19: 603090875 | D19: ASISTENTE TÉCNICO | E19: zcampos@tilaran.go.cr | G19: =1+G18 -> 23 | H19: 30 | I19: puntos
A20: =1+A19 -> 4 | B20: José Antonio Rodríguez Herrera | C20: 108770167 | D20: COORDINADOR | E20: jrodriguez@tilaran.go.cr | G20: =1+G19 -> 24 | H20: 30 | I20: puntos
A21: =1+A20 -> 5 | B21: Rose Mary Ruiz Soto | C21: 109850926 | D21: COORDINADOR DE DESARROLLO Y CONTROL URBANO | E21: rruiz@tilaran.go.cr | G21: =1+G20 -> 25 | H21: 30 | I21: puntos
A22: =1+A21 -> 6 | B22: Rigoberto Hernández Quesada | C22: 603970773 | D22: ENCARGADO DE BIENES INMUEBLES Y VALORACIÓN | E22: rhernandez@tilaran.go.cr | G22: =1+G21 -> 26 | H22: 30 | I22: puntos
A23: =1+A22 -> 7 | B23: Gustavo Bogantes Morera | C23: 109140785 | D23: ENCARGADO DE CATASTRO | E23: gbogantes@tilaran.go.cr | G23: =1+G22 -> 27 | H23: 30 | I23: puntos
A24: =1+A23 -> 8 | B24: Jimmy Espinoza Masis | C24: 108440863 | D24: INSPECTOR | E24: jespinoza@tilaran.go.cr | G24: =1+G23 -> 28 | H24: 30 | I24: puntos
A25: =1+A24 -> 9 | B25: Brallan Vasquez Reyes | C25: 207080293 | D25: INSPECTOR | E25: bvasquez@tilaran.go.cr | G25: =1+G24 -> 29 | H25: 30 | I25: puntos
A26: =1+A25 -> 10 | B26: Uber Alberto Masis Solis | C26: 502950045 | D26: INSPECTOR | E26: hmasis@tilaran.go.cr | G26: =1+G25 -> 30 | H26: 30 | I26: puntos
A27: =1+A26 -> 11 | B27: Annia Ramírez Rodríguez | C27: 502820803 | D27: PLATAFORMISTA | E27: aramirez@tilaran.go.cr | G27: =1+G26 -> 31 | H27: 20 | I27: puntos
A28: =1+A27 -> 12 | B28: Graciela Lopez Granados | C28: 504270106 | D28: PLATAFORMISTA | E28: fperez@tilaran.go.cr | G28: =1+G27 -> 32 | H28: 20 | I28: puntos
A29: =1+A28 -> 13 | B29: Gerald José Vega Zamora | C29: 116680794 | D29: PLATAFORMISTA | E29: geraldvegazamora@gmail.com | G29: =1+G28 -> 33 | H29: 20 | I29: puntos
... A31: =1+A30 -> 15 | B31: Mario Humberto Alvarado Barrantes | C31: 504110305 | D31: PLATAFORMISTA | E31: mario.alvarado@tilaran.go.cr | G31: =1+G30 -> 35 | H31: 20 | I31: puntos
A32: =1+A31 -> 16 | G32: =1+G31 -> 36 | H32: 20 | I32: puntos
A33: =1+A32 -> 17 | G33: =1+G32 -> 37 | H33: 20 | I33: puntos
A34: =1+A33 -> 18 | G34: =1+G33 -> 38 | H34: 20 | I34: puntos
G35: =1+G34 -> 39 | H35: 20 | I35: puntos
G36: =1+G35 -> 40 | H36: 20 | I36: puntos
G37: =1+G36 -> 41 | H37: 20 | I37: puntos
G38: =1+G37 -> 42 | H38: 20 | I38: puntos
G39: =1+G38 -> 43 | H39: 20 | I39: puntos
G40: =1+G39 -> 44 | H40: 20 | I40: puntos
G41: =1+G40 -> 45 | H41: 20 | I41: puntos
G42: =1+G41 -> 46 | H42: 20 | I42: puntos
C43: X | G43: =1+G42 -> 47 | H43: 20 | I43: puntos
...
